#VRML_SIM R2022a utf8
WorldInfo {
}
Viewpoint {
  orientation 0.4126618312996178 0.01055314800808255 -0.9108231683787832 3.0950086130690835
  position 1.6967408087505342 -0.15554521136833355 1.7041511720259443
}
TexturedBackground {
}
TexturedBackgroundLight {
}
RectangleArena {
  translation 0 0 0.01
  floorSize 5 5
}
E-puck {
  translation 0 0.33 0
}
WaterBottle {
  translation -0.4 -0.55 0
}
Can {
  translation 0.07 -0.28 0.06
}
Robot {
  translation 0.630001 -1.11256e-15 0.0497071
  rotation 1.4957077868227269e-10 1 -9.181809147929692e-11 1.9583546280551812e-05
  children [
    DEF body Shape {
      appearance PBRAppearance {
        baseColor 0 0 1
      }
      geometry Box {
        size 0.1 0.2 0.05
      }
    }
    HingeJoint {
      jointParameters HingeJointParameters {
        anchor 0.06 0.05 0
      }
      device [
        RotationalMotor {
          name "wheel1"
        }
      ]
      endPoint Solid {
        translation 0.06 0.05 0
        rotation 1.5707179855829956e-16 1 7.853589927914978e-17 1.5700000000000003
        children [
          DEF wheel Shape {
            appearance PBRAppearance {
              baseColor 0.8 0 0.2
            }
            geometry Cylinder {
              height 0.02
              radius 0.04
            }
          }
        ]
        boundingObject USE wheel
        physics DEF Physics_wh Physics {
        }
      }
    }
    HingeJoint {
      jointParameters HingeJointParameters {
        position -2.3989060338180934e-07
        anchor -0.06 -0.05 0
      }
      device [
        RotationalMotor {
          name "wheel2"
        }
      ]
      endPoint Solid {
        translation -0.06 -0.05 0
        rotation 6.086347571377412e-17 1 8.333830043445891e-17 1.5700000000000007
        children [
          USE wheel
        ]
        name "solid(3)"
        boundingObject USE wheel
        physics USE Physics_wh
      }
    }
    HingeJoint {
      jointParameters HingeJointParameters {
        anchor -0.06 0.05 0
      }
      device [
        RotationalMotor {
          name "wheel3"
        }
      ]
      endPoint Solid {
        translation -0.06 0.05 0
        rotation -1.570717985582996e-16 1 0 1.5699999999999996
        children [
          USE wheel
        ]
        name "solid(1)"
        boundingObject USE wheel
        physics USE Physics_wh
      }
    }
    HingeJoint {
      jointParameters HingeJointParameters {
        anchor 0.06 -0.05 0
      }
      device [
        RotationalMotor {
          name "wheel4"
        }
      ]
      endPoint Solid {
        translation 0.059999999999999915 -0.04999999999999996 1.68485873080222e-18
        rotation -1.9633974819787457e-16 1 3.9267949639574913e-17 1.5699999999999994
        children [
          USE wheel
        ]
        name "solid(2)"
        boundingObject USE wheel
        physics USE Physics_wh
      }
    }
    DistanceSensor {
      translation 0.028653 -0.0911116 0
      rotation 0 0 1 -1.27
      children [
        DEF sensor Shape {
          appearance PBRAppearance {
            baseColor 0 1 1
            metalness 0
          }
          geometry Box {
            size 0.01 0.01 0.01
          }
        }
      ]
      name "ds_left"
      boundingObject USE sensor
      physics Physics {
      }
    }
    DistanceSensor {
      translation -0.0486671 -0.0911572 0
      rotation 0 0 -1 1.87
      children [
        DEF sensor Shape {
          appearance PBRAppearance {
            baseColor 0 1 1
            metalness 0
          }
          geometry Box {
            size 0.01 0.01 0.01
          }
        }
      ]
      name "ds_right"
      boundingObject USE sensor
      physics Physics {
      }
    }
  ]
  boundingObject USE body
  physics Physics {
  }
  recognitionColors [
    0 0 0
  ]
  controller "controladormovilidad"
}
